Workbook
Name Company_Name: Cover!#REF!

Sheet Cover
B3: The Boeing Company
B7: Three Statement Financial Model & DCF Valuation
B10: Prepared by | D10: Tim Nguyen
B11: Date | D11: =TODAY() -> 46135

Sheet Assumptions
B2: Assumptions | C2: 2021 | D2: =+C2+1 -> 2022 | E2: =+D2+1 -> 2023 | F2: =+E2+1 -> 2024 | G2: =+F2+1 -> 2025 | H2: =+G2+1 -> 2026 | I2: =+H2+1 -> 2027 | J2: =+I2+1 -> 2028 | K2: =+J2+1 -> 2029 | L2: =+K2+1 -> 2030
B3: Revenue and Growth
B4: Revenue Growth Rate (%) | C4: 0 | D4: ='3 Statement Model'!D4/'3 Statement Model'!C4 - 1 -> 0.06938959 | E4: ='3 Statement Model'!E4/'3 Statement Model'!D4 - 1 -> 0.16793779 | F4: ='3 Statement Model'!F4/'3 Statement Model'!E4 - 1 -> -0.14495977 | G4: ='3 Statement Model'!G4/'3 Statement Model'!F4 - 1 -> 0.34496445 | H4: =RATE(4,0,-'3 Statement Model'!$C$4,'3 Statement Model'!$G$4) -> 0.094745715 | I4: =RATE(4,0,-'3 Statement Model'!$C$4,'3 Statement Model'!$G$4) -> 0.094745715 | J4: =RATE(4,0,-'3 Statement Model'!$C$4,'3 Statement Model'!$G$4) -> 0.094745715 | K4: =RATE(4,0,-'3 Statement Model'!$C$4,'3 Statement Model'!$G$4) -> 0.094745715 | L4: =RATE(4,0,-'3 Statement Model'!$C$4,'3 Statement Model'!$G$4) -> 0.094745715
B5: Profitability
B6: Gross Margin % | C6: ='3 Statement Model'!C6/'3 Statement Model'!C4 -> 0.04895161 | D6: ='3 Statement Model'!D6/'3 Statement Model'!D4 -> 0.052996637 | E6: ='3 Statement Model'!E6/'3 Statement Model'!E4 -> 0.099287863 | F6: ='3 Statement Model'!F6/'3 Statement Model'!F4 -> -0.029932198 | G6: ='3 Statement Model'!G6/'3 Statement Model'!G4 -> 0.047941607
B7: COGS % of Revenue | C7: ='3 Statement Model'!C5/'3 Statement Model'!C4 -> 0.95104839 | D7: ='3 Statement Model'!D5/'3 Statement Model'!D4 -> 0.94700336 | E7: ='3 Statement Model'!E5/'3 Statement Model'!E4 -> 0.90071214 | F7: ='3 Statement Model'!F5/'3 Statement Model'!F4 -> 1.0299322 | G7: ='3 Statement Model'!G5/'3 Statement Model'!G4 -> 0.95205839
B8: SG&A % of Revenue | C8: ='3 Statement Model'!C8/'3 Statement Model'!C4 -> 0.06674052 | D8: ='3 Statement Model'!D8/'3 Statement Model'!D4 -> 0.062860317 | E8: ='3 Statement Model'!E8/'3 Statement Model'!E4 -> 0.066431858 | F8: ='3 Statement Model'!F8/'3 Statement Model'!F4 -> 0.075484463 | G8: ='3 Statement Model'!G8/'3 Statement Model'!G4 -> 0.068072835
B9: R&D % of Revenue | C9: ='3 Statement Model'!C9/'3 Statement Model'!C4 -> 0.036107633 | D9: ='3 Statement Model'!D9/'3 Statement Model'!D4 -> 0.04281768 | E9: ='3 Statement Model'!E9/'3 Statement Model'!E4 -> 0.043409517 | F9: ='3 Statement Model'!F9/'3 Statement Model'!F4 -> 0.057308658 | G9: ='3 Statement Model'!G9/'3 Statement Model'!G4 -> 0.040407766
B10: EBIT Margin % | C10: ='3 Statement Model'!C11/'3 Statement Model'!C4 -> -0.053896542 | D10: ='3 Statement Model'!D11/'3 Statement Model'!D4 -> -0.05268136 | E10: ='3 Statement Model'!E11/'3 Statement Model'!E4 -> -0.010553513 | F10: ='3 Statement Model'!F11/'3 Statement Model'!F4 -> -0.16272532 | G10: ='3 Statement Model'!G11/'3 Statement Model'!G4 -> -0.060538994
B11: Net Income Margin % | C11: ='3 Statement Model'!C18/'3 Statement Model'!C4 -> -0.068875831 | D11: ='3 Statement Model'!D18/'3 Statement Model'!D4 -> -0.075861758 | E11: ='3 Statement Model'!E18/'3 Statement Model'!E4 -> -0.028819703 | F11: ='3 Statement Model'!F18/'3 Statement Model'!F4 -> -0.17783424 | G11: ='3 Statement Model'!G18/'3 Statement Model'!G4 -> 0.025015928
B12: Tax
B13: Effective Tax Rate | C13: 0 | D13: 0 | E13: 0 | F13: 0 | G13: ='3 Statement Model'!G17/'3 Statement Model'!G16 -> 0.15066414 | H13: 0.21 | I13: 0.21 | J13: 0.21 | K13: 0.21 | L13: 0.21
B14: Capital Expenditure
B15: Capex % of Revenue | C15: ='3 Statement Model'!C92/'3 Statement Model'!C4 -> -0.015733873 | D15: ='3 Statement Model'!D92/'3 Statement Model'!D4 -> -0.018346145 | E15: ='3 Statement Model'!E92/'3 Statement Model'!E4 -> -0.019628763 | F15: ='3 Statement Model'!F92/'3 Statement Model'!F4 -> -0.033525264 | G15: ='3 Statement Model'!G92/'3 Statement Model'!G4 -> -0.032885103
B16: Capex % of PP&E | C16: ='3 Statement Model'!C92/'3 Statement Model'!C38 -> -0.089760029 | D16: ='3 Statement Model'!D92/'3 Statement Model'!D38 -> -0.11582938 | E16: ='3 Statement Model'!E92/'3 Statement Model'!E38 -> -0.14323234 | F16: ='3 Statement Model'!F92/'3 Statement Model'!F38 -> -0.19540834 | G16: ='3 Statement Model'!G92/'3 Statement Model'!G38 -> -0.19152399
B17: D&A % of Revenue | C17: ='3 Statement Model'!C72/'3 Statement Model'!C4 -> 0.03442186 | D17: ='3 Statement Model'!D72/'3 Statement Model'!D4 -> 0.029711146 | E17: ='3 Statement Model'!E72/'3 Statement Model'!E4 -> 0.023922153 | F17: ='3 Statement Model'!F72/'3 Statement Model'!F4 -> 0.027601966 | G17: ='3 Statement Model'!G72/'3 Statement Model'!G4 -> 0.021830254
B18: Working Capital
B19: DSO (Days) | C19: ='3 Statement Model'!C31/'3 Statement Model'!C4 *365 -> 15.476431 | D19: ='3 Statement Model'!D31/'3 Statement Model'!D4 *365 -> 13.792713 | E19: ='3 Statement Model'!E31/'3 Statement Model'!E4 *365 -> 12.428786 | F19: ='3 Statement Model'!F31/'3 Statement Model'!F4 *365 -> 14.437136 | G19: ='3 Statement Model'!G31/'3 Statement Model'!G4 *365 -> 11.917385 | H19: =AVERAGE(C19:G19) -> 13.61049 | I19: =AVERAGE(D19:H19) -> 13.237302 | J19: =AVERAGE(E19:I19) -> 13.12622 | K19: =AVERAGE(F19:J19) -> 13.265707 | L19: =AVERAGE(G19:K19) -> 13.031421
B20: DIO (Days | C20: ='3 Statement Model'!C34/'3 Statement Model'!C5 *365 -> 485.68285 | D20: ='3 Statement Model'!D34/'3 Statement Model'!D5 *365 -> 452.21971 | E20: ='3 Statement Model'!E34/'3 Statement Model'!E5 *365 -> 415.37698 | F20: ='3 Statement Model'!F34/'3 Statement Model'!F5 *365 -> 466.45282 | G20: ='3 Statement Model'!G34/'3 Statement Model'!G5 *365 -> 362.87875 | H20: =AVERAGE(E20:G20) -> 414.90285 | I20: =AVERAGE(F20:H20) -> 414.74481 | J20: =AVERAGE(G20:I20) -> 397.50881 | K20: =AVERAGE(H20:J20) -> 409.05216 | L20: =AVERAGE(I20:K20) -> 407.10192
B21: DPO (Days) | C21: ='3 Statement Model'!C45/'3 Statement Model'!C5 *365 -> 57.063406 | D21: ='3 Statement Model'!D45/'3 Statement Model'!D5 *365 -> 59.022163 | E21: ='3 Statement Model'!E45/'3 Statement Model'!E5 *365 -> 62.321393 | F21: ='3 Statement Model'!F45/'3 Statement Model'!F5 *365 -> 60.54563 | G21: ='3 Statement Model'!G45/'3 Statement Model'!G5 *365 -> 56.176591 | H21: =AVERAGE(C21:G21) -> 59.025837 | I21: =AVERAGE(D21:H21) -> 59.418323 | J21: =AVERAGE(E21:I21) -> 59.497555 | K21: =AVERAGE(F21:J21) -> 58.932787 | L21: =AVERAGE(G21:K21) -> 58.610219
B22: Advances & Billings % of Revenue | C22: ='3 Statement Model'!C47/'3 Statement Model'!C4 -> 0.85059243 | D22: ='3 Statement Model'!D47/'3 Statement Model'!D4 -> 0.79691629 | E22: ='3 Statement Model'!E47/'3 Statement Model'!E4 -> 0.72406612 | F22: ='3 Statement Model'!F47/'3 Statement Model'!F4 -> 0.90703129 | G22: ='3 Statement Model'!G47/'3 Statement Model'!G4 -> 0.66400635
B23: Leverage & Returns
B24: Net Debt ($M) | C24: ='3 Statement Model'!C54+'3 Statement Model'!C48-'3 Statement Model'!C29-'3 Statement Model'!C30 -> 41858 | D24: ='3 Statement Model'!D54+'3 Statement Model'!D48-'3 Statement Model'!D29-'3 Statement Model'!D30 -> 39781 | E24: ='3 Statement Model'!E54+'3 Statement Model'!E48-'3 Statement Model'!E29-'3 Statement Model'!E30 -> 36342 | F24: ='3 Statement Model'!F54+'3 Statement Model'!F48-'3 Statement Model'!F29-'3 Statement Model'!F30 -> 27582 | G24: ='3 Statement Model'!G54+'3 Statement Model'!G48-'3 Statement Model'!G29-'3 Statement Model'!G30 -> 24698 | H24: =AVERAGE(E24:G24) -> 29540.667 | I24: =AVERAGE(F24:H24) -> 27273.556 | J24: =AVERAGE(G24:I24) -> 27170.741 | K24: =AVERAGE(H24:J24) -> 27994.988 | L24: =AVERAGE(I24:K24) -> 27479.761
B25: Net Debt / EBITDA | C25: =IF(C24/('3 Statement Model'!C11+'3 Statement Model'!C72)<0, "nm", C24/('3 Statement Model'!C11+'3 Statement Model'!C72)) -> nm | D25: =IF(D24/('3 Statement Model'!D11+'3 Statement Model'!D72)<0, "nm", D24/('3 Statement Model'!D11+'3 Statement Model'!D72)) -> nm | E25: =IF(E24/('3 Statement Model'!E11+'3 Statement Model'!E72)<0, "nm", E24/('3 Statement Model'!E11+'3 Statement Model'!E72)) -> 34.944231 | F25: =IF(F24/('3 Statement Model'!F11+'3 Statement Model'!F72)<0, "nm", F24/('3 Statement Model'!F11+'3 Statement Model'!F72)) -> nm | G25: =IF(G24/('3 Statement Model'!G11+'3 Statement Model'!G72)<0, "nm", G24/('3 Statement Model'!G11+'3 Statement Model'!G72)) -> nm
B26: Interest Coverage (x) | C26: =IF('3 Statement Model'!C15/('3 Statement Model'!C54+'3 Statement Model'!C48)<0,"nm",'3 Statement Model'!C15/('3 Statement Model'!C54+'3 Statement Model'!C48)) -> nm | D26: =IF('3 Statement Model'!D15/('3 Statement Model'!D54+'3 Statement Model'!D48)<0,"nm",'3 Statement Model'!D15/('3 Statement Model'!D54+'3 Statement Model'!D48)) -> nm | E26: =IF('3 Statement Model'!E15/('3 Statement Model'!E54+'3 Statement Model'!E48)<0,"nm",'3 Statement Model'!E15/('3 Statement Model'!E54+'3 Statement Model'!E48)) -> nm | F26: =IF('3 Statement Model'!F15/('3 Statement Model'!F54+'3 Statement Model'!F48)<0,"nm",'3 Statement Model'!F15/('3 Statement Model'!F54+'3 Statement Model'!F48)) -> nm | G26: =IF('3 Statement Model'!G15/('3 Statement Model'!G54+'3 Statement Model'!G48)<0,"nm",'3 Statement Model'!G15/('3 Statement Model'!G54+'3 Statement Model'!G48)) -> nm
B27: Interest % of Debt | C27: ='3 Statement Model'!C15/('3 Statement Model'!C54+'3 Statement Model'!C48) -> -0.046710957 | D27: ='3 Statement Model'!D15/('3 Statement Model'!D54+'3 Statement Model'!D48) -> -0.044929036 | E27: ='3 Statement Model'!E15/('3 Statement Model'!E54+'3 Statement Model'!E48) -> -0.047010916 | F27: ='3 Statement Model'!F15/('3 Statement Model'!F54+'3 Statement Model'!F48) -> -0.050590376 | G27: ='3 Statement Model'!G15/('3 Statement Model'!G54+'3 Statement Model'!G48) -> -0.051221857 | H27: =AVERAGE(E27:G27) -> -0.049607716 | I27: =AVERAGE(F27:H27) -> -0.050473316 | J27: =AVERAGE(G27:I27) -> -0.050434296 | K27: =AVERAGE(H27:J27) -> -0.050171776 | L27: =AVERAGE(I27:K27) -> -0.050359796

Sheet 3 Statement Model
B3: Income Statement | C3: 2021 | D3: =+C3+1 -> 2022 | E3: =+D3+1 -> 2023 | F3: =+E3+1 -> 2024 | G3: =+F3+1 -> 2025 | H3: =+G3+1 -> 2026 | I3: =+H3+1 -> 2027 | J3: =+I3+1 -> 2028 | K3: =+J3+1 -> 2029 | L3: =+K3+1 -> 2030
B4: Revenue | C4: 62286 | D4: 66608 | E4: 77794 | F4: 66517 | G4: 89463 | H4: =G4*(1+Assumptions!H4) -> 97939.236 | I4: =H4*(1+Assumptions!I4) -> 107218.56 | J4: =I4*(1+Assumptions!J4) -> 117377.06 | K4: =J4*(1+Assumptions!K4) -> 128498.03 | L4: =K4*(1+Assumptions!L4) -> 140672.67
B5: Cost of Goods Sold (COGS) | C5: 59237 | D5: 63078 | E5: 70070 | F5: 68508 | G5: 85174 | H5: =H4*Assumptions!G7 -> 93243.872
B6: Gross Profit | C6: =SUM(C4-C5) -> 3049 | D6: =SUM(D4-D5) -> 3530 | E6: =SUM(E4-E5) -> 7724 | F6: =SUM(F4-F5) -> -1991 | G6: =SUM(G4-G5) -> 4289 | H6: =SUM(H4-H5) -> 4695.3644 | I6: =SUM(I4-I5) -> 107218.56 | J6: =SUM(J4-J5) -> 117377.06 | ... L6: =SUM(L4-L5) -> 140672.67
B7: Expenses
B8: SG&A Expenses | C8: 4157 | D8: 4187 | E8: 5168 | F8: 5021 | G8: 6090 | H8: =H4*Assumptions!G8 -> 6667.0014
B9: Research and Development | C9: 2249 | D9: 2852 | E9: 3377 | F9: 3812 | G9: 3615 | H9: =H4*Assumptions!G9 -> 3957.5058
B10: Operating Expenses | C10: =SUM(C8:C9) -> 6406 | D10: =SUM(D8:D9) -> 7039 | E10: =SUM(E8:E9) -> 8545 | F10: =SUM(F8:F9) -> 8833 | G10: =SUM(G8:G9) -> 9705 | H10: =SUM(H8:H9) -> 10624.507 | I10: =SUM(I8:I9) -> 0 | J10: =SUM(J8:J9) -> 0 | ... L10: =SUM(L8:L9) -> 0
B11: Operating Income (EBIT) | C11: =SUM(C6-C10) -> -3357 | D11: =SUM(D6-D10) -> -3509 | E11: =SUM(E6-E10) -> -821 | F11: =SUM(F6-F10) -> -10824 | G11: =SUM(G6-G10) -> -5416 | H11: =SUM(H6-H10) -> -5929.1428 | I11: =SUM(I6-I10) -> 107218.56 | J11: =SUM(J6-J10) -> 117377.06 | ... L11: =SUM(L6-L10) -> 140672.67
B12: Income from Operating Investments, Net | C12: 210 | D12: -16 | E12: 46 | F12: 71 | G12: 25 | H12: =AVERAGE(E12:G12) -> 47.333333 | I12: =AVERAGE(F12:H12) -> 47.777778 | J12: =AVERAGE(G12:I12) -> 40.037037 | K12: =AVERAGE(H12:J12) -> 45.049383 | L12: =AVERAGE(I12:K12) -> 44.288066
B13: Gains on Dispositions, Net | C13: 277 | D13: 6 | E13: 2 | F13: 46 | G13: 9672 | H13: 0 | I13: 0 | J13: 0 | K13: 0 | L13: 0
B14: Other Income | C14: 551 | D14: 1058 | E14: 1227 | F14: 1222 | G14: 1125 | H14: =AVERAGE(E14:G14) -> 1191.3333 | I14: =AVERAGE(F14:H14) -> 1179.4444 | J14: =AVERAGE(G14:I14) -> 1165.2593 | K14: =AVERAGE(H14:J14) -> 1178.679 | L14: =AVERAGE(I14:K14) -> 1174.4609
B15: Interest Expense | C15: =-2714 -> -2714 | D15: -2561 | E15: -2459 | F15: -2725 | G15: -2771
B16: Earnings Before Tax (EBT) | C16: =SUM(C11:C15) -> -5033 | D16: =SUM(D11:D15) -> -5022 | E16: =SUM(E11:E15) -> -2005 | F16: =SUM(F11:F15) -> -12210 | G16: =SUM(G11:G15) -> 2635 | H16: =SUM(H11:H15) -> -4690.4761 | I16: =SUM(I11:I15) -> 108445.78 | J16: =SUM(J11:J15) -> 118582.35 | ... L16: =SUM(L11:L15) -> 141891.42
B17: Taxes | C17: -743 | D17: 31 | E17: 237 | F17: -381 | G17: 397 | H17: =H16*Assumptions!H13 -> -984.99999
B18: Net Earnings (Net Income) | C18: =SUM(C16-C17) -> -4290 | D18: =SUM(D16-D17) -> -5053 | E18: =SUM(E16-E17) -> -2242 | F18: =SUM(F16-F17) -> -11829 | G18: =SUM(G16-G17) -> 2238 | H18: =SUM(H16-H17) -> -3705.4761
B19: Less: Noncontrolling Interests | C19: -88 | D19: -118 | E19: -20 | F19: -12 | G19: 3 | H19: =AVERAGE(E19:G19) -> -9.6666667 | I19: =AVERAGE(F19:H19) -> -6.2222222 | J19: =AVERAGE(G19:I19) -> -4.2962963 | K19: =AVERAGE(H19:J19) -> -6.7283951 | L19: =AVERAGE(I19:K19) -> -5.7489712
B20: Net Earnings to Boeing Shareholders | C20: =SUM(C18-C19) -> -4202 | D20: =SUM(D18-D19) -> -4935 | E20: =SUM(E18-E19) -> -2222 | F20: =SUM(F18-F19) -> -11817 | G20: =SUM(G18-G19) -> 2235 | H20: =SUM(H18-H19) -> -3695.8095 | I20: =SUM(I18-I19) -> 6.2222222 | J20: =SUM(J18-J19) -> 4.2962963 | ... L20: =SUM(L18-L19) -> 5.7489712
B21: Less: Mandatory Convertible Preferred Dividends | C21: 0 | D21: 0 | E21: 0 | F21: 58 | G21: -345 | H21: -345 | I21: -173 | J21: 0 | K21: 0 | L21: 0
B22: Net Earnings to Common Shareholders | C22: =SUM(C20-C21) -> -4202 | D22: =SUM(D20-D21) -> -4935 | E22: =SUM(E20-E21) -> -2222 | F22: =SUM(F20-F21) -> -11875 | G22: =SUM(G20:G21) -> 1890 | H22: =SUM(H20:H21) -> -4040.8095 | I22: =SUM(I20:I21) -> -166.77778 | J22: =SUM(J20:J21) -> 4.2962963 | K22: =SUM(K20:K21) -> 6.7283951 | L22: =SUM(L20:L21) -> 5.7489712
B23: Basic Shares Outstanding (Millions) | C23: 587.6 | D23: 594.9 | E23: 605.8 | F23: 646.9 | G23: 759.8 | H23: =AVERAGE(E23:G23) -> 670.83333 | I23: =AVERAGE(F23:H23) -> 692.51111 | J23: =AVERAGE(G23:I23) -> 707.71481 | K23: =AVERAGE(H23:J23) -> 690.35309 | L23: =AVERAGE(I23:K23) -> 696.85967
B24: Basic EPS | C24: =C22/C23 -> -7.1511232 | D24: =D22/D23 -> -8.2955119 | E24: =E22/E23 -> -3.6678772 | F24: =F22/F23 -> -18.356778 | G24: =G22/G23 -> 2.4874967 | H24: =H22/H23 -> -6.0235669 | I24: =I22/I23 -> -0.24083047 | J24: =J22/J23 -> 0.0060706604 | ... L24: =L22/L23 -> 0.0082498262
B25: Diluted Shares Outstanding (Millions | C25: 587.6 | D25: 594.9 | E25: 605.8 | F25: 646.9 | G25: 762.3 | H25: =AVERAGE(E25:G25) -> 671.66667 | I25: =AVERAGE(F25:H25) -> 693.62222 | J25: =AVERAGE(G25:I25) -> 709.1963 | K25: =AVERAGE(H25:J25) -> 691.49506 | L25: =AVERAGE(I25:K25) -> 698.10453
B26: Diluted Basic EPS | C26: =C22/C25 -> -7.1511232 | D26: =D22/D25 -> -8.2955119 | E26: =E22/E25 -> -3.6678772 | F26: =F22/F25 -> -18.356778 | G26: =G22/G25 -> 2.4793388 | H26: =H22/H25 -> -6.0160935 | I26: =I22/I25 -> -0.24044469 | J26: =J22/J25 -> 0.006057979 | ... L26: =L22/L25 -> 0.0082351152
B28: Balance Statement | C28: 2021 | D28: =+C28+1 -> 2022 | E28: =+D28+1 -> 2023 | F28: =+E28+1 -> 2024 | G28: =+F28+1 -> 2025 | H28: =+G28+1 -> 2026 | I28: =+H28+1 -> 2027 | J28: =+I28+1 -> 2028 | K28: =+J28+1 -> 2029 | L28: =+K28+1 -> 2030
B29: Cash | C29: 8052 | D29: 14614 | E29: 12691 | F29: 13801 | G29: 10921
B30: Short-term Investments | C30: 8192 | D30: 2606 | E30: 3274 | F30: 12481 | G30: 18479
B31: Accounts Receivables | C31: 2641 | D31: 2517 | E31: 2649 | F31: 2631 | G31: 2921
B32: Unbilled Receivables | C32: 8620 | D32: 8634 | E32: 8317 | F32: 8363 | G32: 9158
B33: Current Portion of Financing Receivables | C33: 117 | D33: 154 | E33: 99 | F33: 207 | G33: 0
B34: Inventory | C34: 78823 | D34: 78151 | E34: 79741 | F34: 87550 | G34: 84679
B35: Other Current Assets | C35: 2221 | D35: 2847 | E35: 2504 | F35: 2965 | G35: 2301
B36: Total Current Assets | C36: =SUM(C29:C35) -> 108666 | D36: =SUM(D29:D35) -> 109523 | E36: =SUM(E29:E35) -> 109275 | F36: =SUM(F29:F35) -> 127998 | G36: =SUM(G29:G35) -> 128459
B37: Financing Receivables and Operating Lease Equipment, Net | C37: 1695 | D37: 1450 | E37: 860 | F37: 314 | G37: 241
B38: PP&E | C38: 10918 | D38: 10550 | E38: 10661 | F38: 11412 | G38: 15361
B39: Goodwill | C39: 8068 | D39: 8057 | E39: 8093 | F39: 8084 | G39: 17275
B40: Acquired Intangibles Assets, Net | C40: 2562 | D40: 2311 | E40: 2094 | F40: 1957 | G40: 1567
B41: Deferred Income Taxes | C41: 77 | D41: 63 | E41: 59 | F41: 185 | G41: 107
B42: Investments | C42: 975 | D42: 983 | E42: 1035 | F42: 999 | G42: 1048
B43: Other Current Assets | C43: 5591 | D43: 4163 | E43: 4935 | F43: 5414 | G43: 4177
...
